<?xml version="1.0" encoding="utf-8"?>
<!-- =================================================================================== -->
<!-- |    This document was autogenerated by xacro from src/diana7_description/urdf/diana7_robot.urdf.xacro | -->
<!-- |    EDITING THIS FILE BY HAND IS NOT RECOMMENDED                                 | -->
<!-- =================================================================================== -->
<robot name="diana7">
  <gazebo>
    <plugin filename="libgazebo_ros_control.so" name="ros_control">
      <!--robotNamespace>/</robotNamespace-->
      <!--robotSimType>gazebo_ros_control/DefaultRobotHWSim</robotSimType-->
      <!--legacyModeNS>true</legacyModeNS-->
    </plugin>
    <!--
    <plugin name="gazebo_ros_power_monitor_controller" filename="libgazebo_ros_power_monitor.so">
      <alwaysOn>true</alwaysOn>
      <updateRate>1.0</updateRate>
      <timeout>5</timeout>
      <powerStateTopic>power_state</powerStateTopic>
      <powerStateRate>10.0</powerStateRate>
      <fullChargeCapacity>87.78</fullChargeCapacity>     
      <dischargeRate>-474</dischargeRate>
      <chargeRate>525</chargeRate>
      <dischargeVoltage>15.52</dischargeVoltage>
      <chargeVoltage>16.41</chargeVoltage>
    </plugin>
-->
  </gazebo>
  <link name="base_link">
    <inertial>
      <origin rpy="0 0 0" xyz="0.0 0.0 0.0"/>
      <mass value="5.0"/>
      <inertia ixx="0.0" ixy="0.0" ixz="0.0" iyy="0.0" iyz="0.0" izz="0.0"/>
    </inertial>
    <visual>
      <origin rpy="0 0 0" xyz="0 0 0"/>
      <geometry>
        <mesh filename="package://diana7_description/meshes/base_link.STL"/>
      </geometry>
      <material name="LightGrey">
        <color rgba="0.7 0.7 0.7 1"/>
      </material>
    </visual>
    <collision>
      <origin rpy="0 0 0" xyz="0 0 0"/>
      <geometry>
        <mesh filename="package://diana7_description/meshes/base_link.STL"/>
      </geometry>
    </collision>
  </link>
  <joint name="joint1" type="revolute">
    <origin rpy="-3.14159265358 0.0 -0.0" xyz="0.0 -2.9150689157e-12 0.2856"/>
    <parent link="base_link"/>
    <child link="link1"/>
    <axis xyz="0 0 1"/>
    <limit effort="235.0" lower="-3.12413936107" upper="3.12413936107" velocity="2.967059728"/>
    <dynamics damping="0.0" friction="0.1"/>
  </joint>
  <joint name="joint2" type="revolute">
    <origin rpy="1.57079632679 -0.0 -0.0" xyz="0.0 -0.0 -0.0"/>
    <parent link="link1"/>
    <child link="link2"/>
    <axis xyz="0 0 1"/>
    <limit effort="235.0" lower="-1.5707963268" upper="1.5707963268" velocity="2.617993878"/>
    <dynamics damping="0.0" friction="0.1"/>
  </joint>
  <joint name="joint3" type="revolute">
    <origin rpy="-1.57079632679 0.0 -0.0" xyz="0.0 -0.4586 1.60119334199e-15"/>
    <parent link="link2"/>
    <child link="link3"/>
    <axis xyz="0 0 1"/>
    <limit effort="111.0" lower="-3.12413936107" upper="3.12413936107" velocity="2.617993878"/>
    <dynamics damping="0.0" friction="0.1"/>
  </joint>
  <joint name="joint4" type="revolute">
    <origin rpy="1.57079632679 -0.0 -0.0" xyz="0.065 -0.0 -0.0"/>
    <parent link="link3"/>
    <child link="link4"/>
    <axis xyz="0 0 1"/>
    <limit effort="111.0" lower="0.0" upper="3.05432619099" velocity="2.617993878"/>
    <dynamics damping="0.0" friction="0.1"/>
  </joint>
  <joint name="joint5" type="revolute">
    <origin rpy="-1.57079632679 0.0 -0.0" xyz="-0.0528 -0.4554 1.59002060171e-15"/>
    <parent link="link4"/>
    <child link="link5"/>
    <axis xyz="0 0 1"/>
    <limit effort="54.0" lower="-3.12413936107" upper="3.12413936107" velocity="3.14159265359"/>
    <dynamics damping="0.0" friction="0.1"/>
  </joint>
  <joint name="joint6" type="revolute">
    <origin rpy="1.57079632679 -1.02068239345e-11 3.14159265359" xyz="-0.0122 0.0 -0.0"/>
    <parent link="link5"/>
    <child link="link6"/>
    <axis xyz="0 0 1"/>
    <limit effort="54.0" lower="-3.12413936107" upper="3.12413936107" velocity="3.14159265359"/>
    <dynamics damping="0.0" friction="0.1"/>
  </joint>
  <joint name="joint7" type="revolute">
    <origin rpy="-1.57079632679 0.0 -0.0" xyz="0.087 -0.1169 4.08154168511e-16"/>
    <parent link="link6"/>
    <child link="link7"/>
    <axis xyz="0 0 1"/>
    <limit effort="54.0" lower="-3.12413936107" upper="3.12413936107" velocity="3.839724354"/>
    <dynamics damping="0.0" friction="0.1"/>
  </joint>
  <link name="link1">
    <inertial>
      <origin rpy="0 0 0" xyz="-1.7e-05 7e-06 0.03358"/>
      <mass value="5.299828"/>
      <inertia ixx="0.029705" ixy="-3.9e-05" ixz="-2.4e-05" iyy="0.02688" iyz="-7e-05" izz="0.015918"/>
    </inertial>
    <visual>
      <origin rpy="0 0 0" xyz="0 0 0"/>
      <geometry>
        <mesh filename="package://diana7_description/meshes/link1.STL"/>
      </geometry>
      <material name="LightGrey">
        <color rgba="0.7 0.7 0.7 1"/>
      </material>
    </visual>
    <collision>
      <origin rpy="0 0 0" xyz="0 0 0"/>
      <geometry>
        <mesh filename="package://diana7_description/meshes/link1.STL"/>
      </geometry>
    </collision>
  </link>
  <link name="link2">
    <inertial>
      <origin rpy="0 0 0" xyz="-1.5e-05 -0.046026 -0.035713"/>
      <mass value="3.24637"/>
      <inertia ixx="0.020388" ixy="-2e-06" ixz="-0.0" iyy="0.009309" iyz="0.005307" izz="0.01893"/>
    </inertial>
    <visual>
      <origin rpy="0 0 0" xyz="0 0 0"/>
      <geometry>
        <mesh filename="package://diana7_description/meshes/link2.STL"/>
      </geometry>
      <material name="LightGrey">
        <color rgba="0.7 0.7 0.7 1"/>
      </material>
    </visual>
    <collision>
      <origin rpy="0 0 0" xyz="0 0 0"/>
      <geometry>
        <mesh filename="package://diana7_description/meshes/link2.STL"/>
      </geometry>
    </collision>
  </link>
  <link name="link3">
    <inertial>
      <origin rpy="0 0 0" xyz="0.027041 0.001592 0.140231"/>
      <mass value="5.231815"/>
      <inertia ixx="0.117623" ixy="-0.000425" ixz="0.021147" iyy="0.121236" iyz="0.001127" izz="0.019132"/>
    </inertial>
    <visual>
      <origin rpy="0 0 0" xyz="0 0 0"/>
      <geometry>
        <mesh filename="package://diana7_description/meshes/link3.STL"/>
      </geometry>
      <material name="LightGrey">
        <color rgba="0.7 0.7 0.7 1"/>
      </material>
    </visual>
    <collision>
      <origin rpy="0 0 0" xyz="0 0 0"/>
      <geometry>
        <mesh filename="package://diana7_description/meshes/link3.STL"/>
      </geometry>
    </collision>
  </link>
  <link name="link4">
    <inertial>
      <origin rpy="0 0 0" xyz="-0.02611 -0.042551 -0.029657"/>
      <mass value="1.94006"/>
      <inertia ixx="0.009292" ixy="-0.002304" ixz="0.001465" iyy="0.005983" iyz="0.002463" izz="0.009392"/>
    </inertial>
    <visual>
      <origin rpy="0 0 0" xyz="0 0 0"/>
      <geometry>
        <mesh filename="package://diana7_description/meshes/link4.STL"/>
      </geometry>
      <material name="LightGrey">
        <color rgba="0.7 0.7 0.7 1"/>
      </material>
    </visual>
    <collision>
      <origin rpy="0 0 0" xyz="0 0 0"/>
      <geometry>
        <mesh filename="package://diana7_description/meshes/link4.STL"/>
      </geometry>
    </collision>
  </link>
  <link name="link5">
    <inertial>
      <origin rpy="0 0 0" xyz="-0.006541 0.023619 0.19377"/>
      <mass value="2.678626"/>
      <inertia ixx="0.063743" ixy="0.000512" ixz="-0.002363" iyy="0.061192" iyz="0.008513" izz="0.006265"/>
    </inertial>
    <visual>
      <origin rpy="0 0 0" xyz="0 0 0"/>
      <geometry>
        <mesh filename="package://diana7_description/meshes/link5.STL"/>
      </geometry>
      <material name="LightGrey">
        <color rgba="0.7 0.7 0.7 1"/>
      </material>
    </visual>
    <collision>
      <origin rpy="0 0 0" xyz="0 0 0"/>
      <geometry>
        <mesh filename="package://diana7_description/meshes/link5.STL"/>
      </geometry>
    </collision>
  </link>
  <link name="link6">
    <inertial>
      <origin rpy="0 0 0" xyz="0.048158 -0.01544 0.001272"/>
      <mass value="2.856811"/>
      <inertia ixx="0.007152" ixy="0.001764" ixz="0.000167" iyy="0.010739" iyz="-5.3e-05" izz="0.011456"/>
    </inertial>
    <visual>
      <origin rpy="0 0 0" xyz="0 0 0"/>
      <geometry>
        <mesh filename="package://diana7_description/meshes/link6.STL"/>
      </geometry>
      <material name="LightGrey">
        <color rgba="0.7 0.7 0.7 1"/>
      </material>
    </visual>
    <collision>
      <origin rpy="0 0 0" xyz="0 0 0"/>
      <geometry>
        <mesh filename="package://diana7_description/meshes/link6.STL"/>
      </geometry>
    </collision>
  </link>
  <link name="link7">
    <inertial>
      <origin rpy="0 0 0" xyz="0.000488 0.0 0.03826"/>
      <mass value="0.575995"/>
      <inertia ixx="0.000876" ixy="0.0" ixz="6e-06" iyy="0.000891" iyz="0.0" izz="0.000481"/>
    </inertial>
    <visual>
      <origin rpy="0 0 0" xyz="0 0 0"/>
      <geometry>
        <mesh filename="package://diana7_description/meshes/link7.STL"/>
      </geometry>
      <material name="LightGrey">
        <color rgba="0.7 0.7 0.7 1"/>
      </material>
    </visual>
    <collision>
      <origin rpy="0 0 0" xyz="0 0 0"/>
      <geometry>
        <mesh filename="package://diana7_description/meshes/link7.STL"/>
      </geometry>
    </collision>
  </link>
  <transmission name="joint1_trans">
    <type>transmission_interface/SimpleTransmission</type>
    <joint name="joint1">
      <hardwareInterface>hardware_interface/PositionJointInterface</hardwareInterface>
    </joint>
    <actuator name="joint1_motor">
      <mechanicalReduction>1</mechanicalReduction>
    </actuator>
  </transmission>
  <transmission name="joint2_trans">
    <type>transmission_interface/SimpleTransmission</type>
    <joint name="joint2">
      <hardwareInterface>hardware_interface/PositionJointInterface</hardwareInterface>
    </joint>
    <actuator name="joint2_motor">
      <mechanicalReduction>1</mechanicalReduction>
    </actuator>
  </transmission>
  <transmission name="joint3_trans">
    <type>transmission_interface/SimpleTransmission</type>
    <joint name="joint3">
      <hardwareInterface>hardware_interface/PositionJointInterface</hardwareInterface>
    </joint>
    <actuator name="joint3_motor">
      <mechanicalReduction>1</mechanicalReduction>
    </actuator>
  </transmission>
  <transmission name="joint4_trans">
    <type>transmission_interface/SimpleTransmission</type>
    <joint name="joint4">
      <hardwareInterface>hardware_interface/PositionJointInterface</hardwareInterface>
    </joint>
    <actuator name="joint4_motor">
      <mechanicalReduction>1</mechanicalReduction>
    </actuator>
  </transmission>
  <transmission name="joint5_trans">
    <type>transmission_interface/SimpleTransmission</type>
    <joint name="joint5">
      <hardwareInterface>hardware_interface/PositionJointInterface</hardwareInterface>
    </joint>
    <actuator name="joint5_motor">
      <mechanicalReduction>1</mechanicalReduction>
    </actuator>
  </transmission>
  <transmission name="joint6_trans">
    <type>transmission_interface/SimpleTransmission</type>
    <joint name="joint6">
      <hardwareInterface>hardware_interface/PositionJointInterface</hardwareInterface>
    </joint>
    <actuator name="joint6_motor">
      <mechanicalReduction>1</mechanicalReduction>
    </actuator>
  </transmission>
  <transmission name="joint7_trans">
    <type>transmission_interface/SimpleTransmission</type>
    <joint name="joint7">
      <hardwareInterface>hardware_interface/PositionJointInterface</hardwareInterface>
    </joint>
    <actuator name="joint7_motor">
      <mechanicalReduction>1</mechanicalReduction>
    </actuator>
  </transmission>
  <gazebo reference="link1">
    <selfCollide>True</selfCollide>
  </gazebo>
  <gazebo reference="link2">
    <selfCollide>True</selfCollide>
  </gazebo>
  <gazebo reference="link3">
    <selfCollide>True</selfCollide>
  </gazebo>
  <gazebo reference="link4">
    <selfCollide>True</selfCollide>
  </gazebo>
  <gazebo reference="link5">
    <selfCollide>True</selfCollide>
  </gazebo>
  <gazebo reference="link6">
    <selfCollide>True</selfCollide>
  </gazebo>
  <gazebo reference="link7">
    <selfCollide>True</selfCollide>
  </gazebo>
  <link name="world"/>
  <joint name="world_joint" type="fixed">
    <parent link="world"/>
    <child link="base_link"/>
    <origin rpy="0.0 0.0 0.0" xyz="0.0 0.0 0.0"/>
  </joint>
</robot>

